Workbook
Name NativeTimeline_Fecha: #N/A
Name NativeTimeline_Fecha1: #N/A
Name NativeTimeline_Fecha2: #N/A

Sheet BD_Cod
A1: SKU | B1: Descripción | C1: Especie | D1: Variedad | E1: Manejo | F1: Calibre | G1: Calidad | H1: Familia Calidad | I1: Formato | J1: Envase | K1: PSP/PTT | L1: Agrupa | M1: PRODUCTO | N1: Precio Odoo
A2: 100001 | B2: AR HB Conv. >12 mm IQF A 13,61 kg en Caja | C2: Arándano | D2: HB | E2: Conv. | F2: >12 mm | G2: IQF A | H2: PTT | I2: 13,61 kg | J2: Caja | K2: Arándano HB Conv. PPT | L2: AR HB Conv.
A3: 100002 | B3: AR HB Conv. >12 mm IQF B 13,61 kg en Caja | C3: Arándano | D3: HB | E3: Conv. | F3: >11 mm | G3: IQF B | H3: PTT | I3: 13,61 kg | J3: Caja | K3: Arándano HB Conv. PPT | L3: AR HB Conv.
A4: 100003 | B4: AR RY Conv. >12 mm IQF A 13,61 kg en Caja | C4: Arándano | D4: RY | E4: Conv. | F4: >12 mm | G4: IQF A | H4: PTT | I4: 13,61 kg | J4: Caja | K4: Arándano RY Conv. PPT | L4: AR RY Conv.
A5: 100004 | B5: AR RY Conv. >12 mm IQF B 13,61 kg en Caja | C5: Arándano | D5: RY | E5: Conv. | F5: >12 mm | G5: IQF B | H5: PTT | I5: 13,61 kg | J5: Caja | K5: Arándano RY Conv. PPT | L5: AR RY Conv.
A6: 100005 | B6: AR HB Org. >12 mm IQF A 13,61 kg en Caja | C6: Arándano | D6: HB | E6: Org. | F6: >12 mm | G6: IQF A | H6: PTT | I6: 13,61 kg | J6: Caja | K6: Arándano HB Org. PPT | L6: AR HB Org.
A7: 100006 | B7: AR HB Org. >12 mm IQF B 13,61 kg en Caja | C7: Arándano | D7: HB | E7: Org. | F7: >12 mm | G7: IQF B | H7: PTT | I7: 13,61 kg | J7: Caja | K7: Arándano HB Org. PPT | L7: AR HB Org.
A8: 100007 | B8: AR RY Org. >12 mm IQF A 13,61 kg en Caja | C8: Arándano | D8: RY | E8: Org. | F8: >12 mm | G8: IQF A | H8: PTT | I8: 13,61 kg | J8: Caja | K8: Arándano RY Org. PPT | L8: AR RY Org.
A9: 100008 | B9: AR RY Org. >11 mm IQF B 13,61 kg en Caja | C9: Arándano | D9: RY | E9: Org. | F9: >11 mm | G9: IQF B | H9: PTT | I9: 13,61 kg | J9: Caja | K9: Arándano RY Org. PPT | L9: AR RY Org.
A10: 100009 | B10: FB MK Conv. >12 mm IQF A 4x2,5 kg en Caja | C10: Frambuesa | D10: MK | E10: Conv. | F10: >12 mm | G10: IQF A | H10: PTT | I10: 4x2,5 kg | J10: Caja | K10: Frambuesa MK Conv. PPT | L10: FB MK Conv.
A11: 100010 | B11: FB WF Conv. >12 mm IQF A 4x2,5 kg en Caja | C11: Frambuesa | D11: WF | E11: Conv. | F11: >12 mm | G11: IQF A | H11: PTT | I11: 4x2,5 kg | J11: Caja | K11: Frambuesa MK Conv. PPT | L11: FB WF Conv.
A12: 100011 | B12: FB MK Org. >12 mm IQF A 4x2,5 kg en Caja | C12: Frambuesa | D12: MK | E12: Org. | F12: >12 mm | G12: IQF A | H12: PTT | I12: 4x2,5 kg | J12: Caja | K12: Frambuesa MK Conv. PPT | L12: FB MK Org.
A13: 100012 | B13: FB WF Org. >12 mm IQF A 4x2,5 kg en Caja | C13: Frambuesa | D13: WF | E13: Org. | F13: >12 mm | G13: IQF A | H13: PTT | I13: 4x2,5 kg | J13: Caja | K13: Frambuesa WF Org. PPT | L13: FB WF Org.
... A40: 100039 | B40: Blueberry Retail 1Kg | C40: Blueberries Retail | D40: Blueberries | E40: Conv. | F40: >12 mm | G40: IQF A | H40: Retail | I40: 10x1 Kg | J40: Caja | K40: Arándano HB Conv. PPT | L40: Retail AR Conv.
A41: 100040 | B41: Triple Berry Mix Retail | C41: Triple Berry Mix | D41: Berries | E41: Conv. | F41: S/C | G41: IQF A | H41: Retail | I41: 15x0,5kg | K41: Mix Conv. PPT | L41: Triple Berry Mix.
A42: 100041 | B42: Triple Berries Block | C42: Triple Berry Mix | D42: Berries | E42: Conv. | F42: S/C | G42: Block | H42: PTT | I42: 10x1 Kg | J42: Caja | K42: Mix Conv. PSP | L42: Triple Berry Mix.
A43: 100042 | B43: Triple Berry Mix Retail por Borrar | C43: Triple Berry Mix | D43: Por Borrar | E43: Conv. | F43: S/C | G43: IQF A | H43: Retail | I43: 15x0,5kg | J43: Caja | K43: Mix Conv. PPT | L43: Triple Berry Mix.
A44: 100043 | B44: AR HB Conv. 12-16 mm IQF A 13,61 kg en Caja | C44: Arándano | D44: HB | E44: Conv. | F44: 12-16 mm | G44: IQF A | H44: PTT | I44: 13,61 kg | J44: Caja | K44: Arándano HB Conv. PPT | L44: AR HB Conv.
A45: 100044 | B45: FRUTILLA S/V Conv. S/C IQF A 13,61 kg en Caja | C45: Frutilla | D45: S/V | E45: Conv. | F45: S/C | G45: IQF A | H45: PTT | I45: 13,61 kg | J45: Caja | K45: FT SV Conv. PPT | L45: Frutilla Conv.
A46: 100045 | B46: MORA S/V Conv. S/C IQF A 13,61 kg en Caja | C46: Mora | D46: S/V | E46: Conv. | F46: S/C | G46: IQF A | H46: PPT | I46: 13,61 kg | J46: Caja | K46: Mora SV Conv. PPT | L46: MORA S/V Conv.
A47: 100046 | B47: AR HB Conv. <13 mm IQF A 13,61 kg en Caja | C47: Arándano | D47: HB | E47: Conv. | F47: <13 mm | G47: IQF A | H47: PTT | I47: 13,61 kg | J47: Caja | K47: Arándano HB Conv. PSP | L47: AR HB Conv.
A48: 100047 | B48: AR HB Org. <12 mm PSP 13,61 kg en Caja | C48: Arándano | D48: HB | E48: Org. | F48: <12 mm | G48: IQF A | H48: PSP | I48: 13,61 kg | J48: Caja | K48: Arándano HB Conv. PSP | L48: AR HB Conv.
A49: 100048 | B49: AR HB Conv. <12 mm PSP 13,61 kg en Caja | C49: Arándano | D49: HB | E49: Conv. | F49: <12 mm | G49: PSP | H49: PSP | I49: 13,61 kg | J49: Caja | K49: Arándano HB Conv. PSP | L49: AR HB Conv.
A50: 100049 | B50: AR HB Org. >12 mm IQF B 13,61 kg en Caja | C50: Arándano | D50: HB | E50: Org. | F50: >12 mm | G50: IQF B | H50: PTT | I50: 13,61 kg | J50: Caja | K50: Arándano HB Org. PPT | L50: AR HB Org.
A51: 100050 | B51: AR HB Org. >11 mm PSP 13,61 kg en Caja | C51: Arándano | D51: HB | E51: Org. | F51: >12 mm | G51: PSP | H51: PSP | I51: 13,61 kg | J51: Caja | K51: Arándano HB Org. PSP | L51: AR HB Org.
A52: 100051 | B52: AR HB Conv. >12 mm IQF A+ 13,61 kg en Caja | C52: Arándano | D52: HB | E52: Conv. | F52: >12 mm | G52: IQF A+ | H52: PTT | I52: 13,61 kg | J52: Caja | K52: Arándano HB Conv. PPT | L52: AR HB Conv.
A53: 100052 | B53: AR RY Conv. >15 mm IQF A 13,61 kg en Caja | C53: Arándano | D53: RY | E53: Conv. | F53: >15 mm | G53: IQF A | H53: PTT | I53: 13,61 kg | J53: Caja | K53: Arándano RY Conv. PPT | L53: AR RY Conv.
... A105: 100107 | B105: AR HB DUKE Conv. >14 IQF A 13,61 kg en Caja | C105: Arándano | D105: Duke | E105: Org. | F105: >14 | G105: IQF A | H105: PTT | I105: 13,61 kg | J105: Caja | K105: Arándano HB DUKE Org. PTT | L105: AR HB DUKE Org.
A106: 100108 | B106: Bueno Farms Blueberry Retail 100grs | C106: Arándano | D106: S/V | E106: Conv. | F106: >12 mm | G106: IQF A | H106: Retail | I106: 100x10grs | J106: Caja
A107: 100109 | B107: Bueno Farms Raspberry Retail 100grs | C107: Frambuesa | D107: S/V | E107: Conv. | F107: >12 mm | G107: IQF A | H107: Retail | I107: 100x10grs | J107: Caja
A108: 100110 | B108: Chocolate dipped Conventional raspberries - white and milk chocolate
A109: 100111 | B109: Chocolate dipped Conventional raspberries - white and dark chocolate
A110: 100112 | B110: Arandano Retail GreenFarms 10x1kg | C110: Arándano | D110: S/V | E110: Conv. | F110: S/C | G110: IQF A | H110: Retail | I110: 10x1 Kg | J110: Caja | K110: Arándano HB Conv. PPT | L110: AR HB Conv.
A111: 100113 | B111: Frambuesa entera GreenFarms 10x1kg | C111: frambuesa | D111: S/V | E111: Conv. | F111: S/C | G111: IQF A | H111: Retail | I111: 10x1 Kg | J111: Caja
A112: 100114 | B112: Triple Mix Berries Conv. Alto Trading 1x10 | C112: Triple Berry Mix | D112: S/V | E112: Conv. | F112: S/C | G112: IQF | H112: N/A | I112: 10x1 Kg | J112: Caja | L112: Triple Berry Mix.
A113: 100115 | B113: AR Retail Alto Trading 10x1kg | C113: Arándano | D113: S/V | E113: Conv. | F113: S/C | G113: IQF | H113: N/A | I113: 10x1 Kg | J113: Caja | L113: Retail AR Conv.
A114: 100116 | B114: CR S/V Conv. 18 >mm IQF A 1Kg | C114: Cereza | D114: S/V | E114: Conv. | F114: >18mm | G114: IQF A | H114: N/A | I114: 1kg
A115: 100117 | B115: AR RY Org. >12 mm IQF A 10 kg en Caja | C115: Arándano | D115: RY | E115: Org. | F115: >12 mm | G115: IQF A | H115: PTT | I115: 10 kg | J115: Caja | K115: Arándano RY Org. PPT | L115: AR RY Org.
A116: 100118 | B116: MORA S/V Org. S/C IQF A 12 kg en Caja | C116: Mora | D116: S/V | E116: Org. | F116: S/C | G116: IQF A | H116: PPT | I116: 12 kg | J116: Caja | K116: Mora SV Org. PPT | L116: MORA S/V Org.
A117: 100130 | B117: FB S/V Org. IQF A 4x2,5 kg en Caja | C117: Frambuesa | D117: S/V | E117: Org. | F117: S/C | G117: IQF A | H117: PTT | I117: 4x2,5 kg | J117: Caja
...

Sheet Base de Datos (R.F.)
A1: Fecha | B1: Semana | C1: Turno | D1: Sala | E1: Código | F1: Descripción del Producto | G1: Familia Calidad | H1: N° Pallet | I1: N° Lote | J1: Muestra | K1: Hora Monitoreo | L1: Peso Bolsa | M1: Peso Caja P.T. | N1: T° Prod. | O1: Sellado Bolsa | P1: Sellado Caja | Q1: % de IQF | R1: Desviación de Color | S1: % Desv. Color (≤5%) | T1: Sobremaduro | U1: % Sobremaduro (≤6%) | V1: Daño Mécanico | W1: % Daño Mécanico (≤6%) | X1: Daño Insecto | Y1: % Daño Insc. (≤5%) | Z1: Block | AA1: % Block (≤5%) | AB1: Mohos | AC1: % Mohos (0%) | AD1: Caliz (Und.) (≤2) | AE1: Larvas (Und.) | AF1: Descripción extra 1 | AG1: Valor Extra 1 | AH1: % Extra 1 | AI1: Descripción Extra 2 | AJ1: Valor Extra 2 | AK1: % Extra 2 | AL1: Calibre >16 | AM1: % >16 | AN1: Calibre <16 | AO1: % <16 | AP1: Palos (Un.) (≤18) | AQ1: Caliz (Un.) (≤18) | AR1: Hojas (Un.) (≤18) | AS1: Larvas (Un.) (≤24) | AT1: Vidrio (Un.) (0) | AU1: Madera (Un.) (0) | AV1: Plástico (Un.) (0) | AW1: °Brix (≥8°) | AX1: Sabor | AY1: Olor | AZ1: Suma Defectos | BA1: % Defectos | BB1: Observaciones | BC1: % IQF | BD1: Nombre del/la Análista | BE1: Mat. Extr. Endo. | BF1: Mat. Extr. Exo. | BG1: Filtro Producto | BH1: Filtro Lote | BI1: Filtro Pallet
A2: 46037 | B2: =_xlfn.ISOWEEKNUM(BD_MR_RF[[#This Row],[Fecha]]) -> 3 | C2: 1 | D2: 3 | E2: 304231000 | F2: =IFERROR("" & _xlfn.XLOOKUP(BD_MR_RF[[#This Row],[Código]],BD_Cod!A:A,BD_Cod!B:B), "") -> MO S/V Org. S/C PSP 12 kg en Caja | G2: =IFERROR(" " &_xlfn.XLOOKUP(BD_MR_RF[[#This Row],[Código]],BD_Cod!A:A,BD_Cod!H:H," ")," ") -> PSP | H2: 21219 | I2: 7830 | J2: 1000 | K2: 08:40 | L2: N/A | M2: 12555 | N2: -12.6 | O2: C | P2: C | Q2: =1-BD_MR_RF[[#This Row],[% Defectos]] -> 0.877 | R2: 64 | S2: =+IFERROR((BD_MR_RF[[#This Row],[Desviación de Color]]/BD_MR_RF[[#This Row],[Muestra]]),"0") -> 0.064 | T2: 0 | U2: =+IFERROR((BD_MR_RF[[#This Row],[Sobremaduro]]/BD_MR_RF[[#This Row],[Muestra]]),"0") -> 0 | V2: 0 | W2: =+IFERROR((BD_MR_RF[[#This Row],[Daño Mécanico]]/BD_MR_RF[[#This Row],[Muestra]]),"0") -> 0 | X2: 53 | Y2: =+IFERROR((BD_MR_RF[[#This Row],[Daño Insecto]]/BD_MR_RF[[#This Row],[Muestra]]),"0") -> 0.053 | Z2: 0 | AA2: =+IFERROR((BD_MR_RF[[#This Row],[Block]]/BD_MR_RF[[#This Row],[Muestra]]),"0") -> 0 | AB2: 6 | AC2: =+IFERROR((BD_MR_RF[[#This Row],[Mohos]]/BD_MR_RF[[#This Row],[Muestra]]),"0") -> 0.006 | AD2: 0 | AE2: 0 | AF2: Mat.Extraña (unid) | AG2: 40 | AJ2: 0 | AK2: =+IFERROR((BD_MR_RF[[#This Row],[Valor Extra 2]]/BD_MR_RF[[#This Row],[Muestra]]),"0") -> 0 | AL2: 0 | AM2: =+IFERROR((BD_MR_RF[[#This Row],[Calibre >16]]/BD_MR_RF[[#This Row],[Muestra]]),"0") -> 0 | AN2: 0 | AO2: =+IFERROR((BD_MR_RF[[#This Row],[Calibre <16]]/BD_MR_RF[[#This Row],[Muestra]]),"0") -> 0 | AP2: S/A | AQ2: S/A | AR2: S/A | AS2: S/A | AT2: S/A | AU2: S/A | AV2: S/A | AW2: 13.7 | AX2: C | AY2: C | AZ2: =SUM(BD_MR_RF[[#This Row],[Desviación de Color]]+BD_MR_RF[[#This Row],[Sobremaduro]]+BD_MR_RF[[#This Row],[Daño Mécanico]]+BD_MR_RF[[#This Row],[Daño Insecto]]+BD_MR_RF[[#This Row],[Block]]+BD_MR_RF[[#This Row],[Mohos]]) -> 123 | BA2: =SUM(BD_MR_RF[[#This Row],[% Desv. Color (≤5%)]]+BD_MR_RF[[#This Row],[% Sobremaduro (≤6%)]]+BD_MR_RF[[#This Row],[% Daño Mécanico (≤6%)]]+BD_MR_RF[[#This Row],[% Daño Insc. (≤5%)]]+BD_MR_RF[[#This Row],[% Block (≤5%)]]+BD_MR_RF[[#This Row],[% Mohos (0%)]]) -> 0.123 | BB2: S/O | BC2: =1-BD_MR_RF[[#This Row],[% Defectos]] -> 0.877 | BD2: Benjamin Navarro | BE2: =SUM(BD_MR_RF[[#This Row],[Palos (Un.) (≤18)]:[Larvas (Un.) (≤24)]]) -> 0 | BF2: =SUM(BD_MR_RF[[#This Row],[Vidrio (Un.) (0)]:[Plástico (Un.) (0)]]) -> 0 | BG2: =IF(ISBLANK(BD_MR_RF[[#This Row],[Descripción del Producto]]),"",BD_MR_RF[[#This Row],[Descripción del Producto]]) -> MO S/V Org. S/C PSP 12 kg en Caja | BH2: =IF(ISBLANK(BD_MR_RF[[#This Row],[N° Lote]]),"",BD_MR_RF[[#This Row],[N° Lote]]) -> 7830 | BI2: =IF(ISBLANK(BD_MR_RF[[#This Row],[N° Pallet]]),"",BD_MR_RF[[#This Row],[N° Pallet]]) -> 21219
A3: 46037 | B3: =_xlfn.ISOWEEKNUM(BD_MR_RF[[#This Row],[Fecha]]) -> 3 | C3: 1 | D3: 3 | E3: 304231000 | F3: =IFERROR("" & _xlfn.XLOOKUP(BD_MR_RF[[#This Row],[Código]],BD_Cod!A:A,BD_Cod!B:B), "") -> MO S/V Org. S/C PSP 12 kg en Caja | G3: =IFERROR(" " &_xlfn.XLOOKUP(BD_MR_RF[[#This Row],[Código]],BD_Cod!A:A,BD_Cod!H:H," ")," ") -> PSP | H3: 21219 | I3: 7830 | J3: 1000 | K3: 0.37361111 | L3: N/A | M3: 12575 | N3: -9.6 | O3: C | P3: C | Q3: =1-BD_MR_RF[[#This Row],[% Defectos]] -> 0.894 | R3: 44 | S3: =+IFERROR((BD_MR_RF[[#This Row],[Desviación de Color]]/BD_MR_RF[[#This Row],[Muestra]]),"0") -> 0.044 | T3: 0 | U3: =+IFERROR((BD_MR_RF[[#This Row],[Sobremaduro]]/BD_MR_RF[[#This Row],[Muestra]]),"0") -> 0 | V3: 0 | W3: =+IFERROR((BD_MR_RF[[#This Row],[Daño Mécanico]]/BD_MR_RF[[#This Row],[Muestra]]),"0") -> 0 | X3: 30 | Y3: =+IFERROR((BD_MR_RF[[#This Row],[Daño Insecto]]/BD_MR_RF[[#This Row],[Muestra]]),"0") -> 0.03 | Z3: 32 | AA3: =+IFERROR((BD_MR_RF[[#This Row],[Block]]/BD_MR_RF[[#This Row],[Muestra]]),"0") -> 0.032 | AB3: 0 | AC3: =+IFERROR((BD_MR_RF[[#This Row],[Mohos]]/BD_MR_RF[[#This Row],[Muestra]]),"0") -> 0 | AD3: 1 | AE3: 0 | AG3: 0 | AH3: =+IFERROR((BD_MR_RF[[#This Row],[Valor Extra 1]]/BD_MR_RF[[#This Row],[Muestra]]),"0") -> 0 | AJ3: 0 | AK3: =+IFERROR((BD_MR_RF[[#This Row],[Valor Extra 2]]/BD_MR_RF[[#This Row],[Muestra]]),"0") -> 0 | AL3: 0 | AM3: =+IFERROR((BD_MR_RF[[#This Row],[Calibre >16]]/BD_MR_RF[[#This Row],[Muestra]]),"0") -> 0 | AN3: 0 | AO3: =+IFERROR((BD_MR_RF[[#This Row],[Calibre <16]]/BD_MR_RF[[#This Row],[Muestra]]),"0") -> 0 | AP3: S/A | AQ3: S/A | AR3: S/A | AS3: S/A | AT3: S/A | AU3: S/A | AV3: S/A | AW3: 12.2 | AX3: C | AY3: C | AZ3: =SUM(BD_MR_RF[[#This Row],[Desviación de Color]]+BD_MR_RF[[#This Row],[Sobremaduro]]+BD_MR_RF[[#This Row],[Daño Mécanico]]+BD_MR_RF[[#This Row],[Daño Insecto]]+BD_MR_RF[[#This Row],[Block]]+BD_MR_RF[[#This Row],[Mohos]]) -> 106 | BA3: =SUM(BD_MR_RF[[#This Row],[% Desv. Color (≤5%)]]+BD_MR_RF[[#This Row],[% Sobremaduro (≤6%)]]+BD_MR_RF[[#This Row],[% Daño Mécanico (≤6%)]]+BD_MR_RF[[#This Row],[% Daño Insc. (≤5%)]]+BD_MR_RF[[#This Row],[% Block (≤5%)]]+BD_MR_RF[[#This Row],[% Mohos (0%)]]) -> 0.106 | BB3: S/O | BC3: =1-BD_MR_RF[[#This Row],[% Defectos]] -> 0.894 | BD3: Benjamin Navarro | BE3: =SUM(BD_MR_RF[[#This Row],[Palos (Un.) (≤18)]:[Larvas (Un.) (≤24)]]) -> 0 | BF3: =SUM(BD_MR_RF[[#This Row],[Vidrio (Un.) (0)]:[Plástico (Un.) (0)]]) -> 0 | BG3: =IF(ISBLANK(BD_MR_RF[[#This Row],[Descripción del Producto]]),"",BD_MR_RF[[#This Row],[Descripción del Producto]]) -> MO S/V Org. S/C PSP 12 kg en Caja | BH3: =IF(ISBLANK(BD_MR_RF[[#This Row],[N° Lote]]),"",BD_MR_RF[[#This Row],[N° Lote]]) -> 7830 | BI3: =IF(ISBLANK(BD_MR_RF[[#This Row],[N° Pallet]]),"",BD_MR_RF[[#This Row],[N° Pallet]]) -> 21219
A4: 46037 | B4: =_xlfn.ISOWEEKNUM(BD_MR_RF[[#This Row],[Fecha]]) -> 3 | C4: 1 | D4: 3 | E4: 304231000 | F4: =IFERROR("" & _xlfn.XLOOKUP(BD_MR_RF[[#This Row],[Código]],BD_Cod!A:A,BD_Cod!B:B), "") -> MO S/V Org. S/C PSP 12 kg en Caja | G4: =IFERROR(" " &_xlfn.XLOOKUP(BD_MR_RF[[#This Row],[Código]],BD_Cod!A:A,BD_Cod!H:H," ")," ") -> PSP | H4: 21220 | I4: 7830 | J4: 1000 | K4: 0.37708333 | L4: N/A | M4: 12560 | N4: -6.9 | O4: C | P4: C | Q4: =1-BD_MR_RF[[#This Row],[% Defectos]] -> 0.699 | R4: 78 | S4: =+IFERROR((BD_MR_RF[[#This Row],[Desviación de Color]]/BD_MR_RF[[#This Row],[Muestra]]),"0") -> 0.078 | T4: 0 | U4: =+IFERROR((BD_MR_RF[[#This Row],[Sobremaduro]]/BD_MR_RF[[#This Row],[Muestra]]),"0") -> 0 | V4: 22 | W4: =+IFERROR((BD_MR_RF[[#This Row],[Daño Mécanico]]/BD_MR_RF[[#This Row],[Muestra]]),"0") -> 0.022 | X4: 63 | Y4: =+IFERROR((BD_MR_RF[[#This Row],[Daño Insecto]]/BD_MR_RF[[#This Row],[Muestra]]),"0") -> 0.063 | Z4: 133 | AA4: =+IFERROR((BD_MR_RF[[#This Row],[Block]]/BD_MR_RF[[#This Row],[Muestra]]),"0") -> 0.133 | AB4: 5 | AC4: =+IFERROR((BD_MR_RF[[#This Row],[Mohos]]/BD_MR_RF[[#This Row],[Muestra]]),"0") -> 0.005 | AD4: 4 | AE4: 0 | AF4: aplastado | AG4: 5 | AH4: =+IFERROR((BD_MR_RF[[#This Row],[Valor Extra 1]]/BD_MR_RF[[#This Row],[Muestra]]),"0") -> 0.005 | AJ4: 0 | AK4: =+IFERROR((BD_MR_RF[[#This Row],[Valor Extra 2]]/BD_MR_RF[[#This Row],[Muestra]]),"0") -> 0 | AL4: 0 | AM4: =+IFERROR((BD_MR_RF[[#This Row],[Calibre >16]]/BD_MR_RF[[#This Row],[Muestra]]),"0") -> 0 | AN4: 0 | AO4: =+IFERROR((BD_MR_RF[[#This Row],[Calibre <16]]/BD_MR_RF[[#This Row],[Muestra]]),"0") -> 0 | AP4: S/A | AQ4: S/A | AR4: S/A | AS4: S/A | AT4: S/A | AU4: S/A | AV4: S/A | AW4: 11.4 | AX4: C | AY4: C | AZ4: =SUM(BD_MR_RF[[#This Row],[Desviación de Color]]+BD_MR_RF[[#This Row],[Sobremaduro]]+BD_MR_RF[[#This Row],[Daño Mécanico]]+BD_MR_RF[[#This Row],[Daño Insecto]]+BD_MR_RF[[#This Row],[Block]]+BD_MR_RF[[#This Row],[Mohos]]) -> 301 | BA4: =SUM(BD_MR_RF[[#This Row],[% Desv. Color (≤5%)]]+BD_MR_RF[[#This Row],[% Sobremaduro (≤6%)]]+BD_MR_RF[[#This Row],[% Daño Mécanico (≤6%)]]+BD_MR_RF[[#This Row],[% Daño Insc. (≤5%)]]+BD_MR_RF[[#This Row],[% Block (≤5%)]]+BD_MR_RF[[#This Row],[% Mohos (0%)]]) -> 0.301 | BB4: S/O | BC4: =1-BD_MR_RF[[#This Row],[% Defectos]] -> 0.699 | BD4: Benjamin Navarro | BE4: =SUM(BD_MR_RF[[#This Row],[Palos (Un.) (≤18)]:[Larvas (Un.) (≤24)]]) -> 0 | BF4: =SUM(BD_MR_RF[[#This Row],[Vidrio (Un.) (0)]:[Plástico (Un.) (0)]]) -> 0 | BG4: =IF(ISBLANK(BD_MR_RF[[#This Row],[Descripción del Producto]]),"",BD_MR_RF[[#This Row],[Descripción del Producto]]) -> MO S/V Org. S/C PSP 12 kg en Caja | BH4: =IF(ISBLANK(BD_MR_RF[[#This Row],[N° Lote]]),"",BD_MR_RF[[#This Row],[N° Lote]]) -> 7830 | BI4: =IF(ISBLANK(BD_MR_RF[[#This Row],[N° Pallet]]),"",BD_MR_RF[[#This Row],[N° Pallet]]) -> 21220
A5: 46037 | B5: =_xlfn.ISOWEEKNUM(BD_MR_RF[[#This Row],[Fecha]]) -> 3 | C5: 1 | D5: 3 | E5: 304231000 | F5: =IFERROR("" & _xlfn.XLOOKUP(BD_MR_RF[[#This Row],[Código]],BD_Cod!A:A,BD_Cod!B:B), "") -> MO S/V Org. S/C PSP 12 kg en Caja | G5: =IFERROR(" " &_xlfn.XLOOKUP(BD_MR_RF[[#This Row],[Código]],BD_Cod!A:A,BD_Cod!H:H," ")," ") -> PSP | H5: 21221 | I5: 7830 | J5: 1000 | K5: 0.39027778 | L5: N/A | M5: 12555 | N5: -14.2 | O5: C | P5: C | Q5: =1-BD_MR_RF[[#This Row],[% Defectos]] -> 0.861 | R5: 19 | S5: =+IFERROR((BD_MR_RF[[#This Row],[Desviación de Color]]/BD_MR_RF[[#This Row],[Muestra]]),"0") -> 0.019 | T5: 0 | U5: =+IFERROR((BD_MR_RF[[#This Row],[Sobremaduro]]/BD_MR_RF[[#This Row],[Muestra]]),"0") -> 0 | V5: 18 | W5: =+IFERROR((BD_MR_RF[[#This Row],[Daño Mécanico]]/BD_MR_RF[[#This Row],[Muestra]]),"0") -> 0.018 | X5: 70 | Y5: =+IFERROR((BD_MR_RF[[#This Row],[Daño Insecto]]/BD_MR_RF[[#This Row],[Muestra]]),"0") -> 0.07 | Z5: 32 | AA5: =+IFERROR((BD_MR_RF[[#This Row],[Block]]/BD_MR_RF[[#This Row],[Muestra]]),"0") -> 0.032 | AB5: 0 | AC5: =+IFERROR((BD_MR_RF[[#This Row],[Mohos]]/BD_MR_RF[[#This Row],[Muestra]]),"0") -> 0 | AD5: 1 | AE5: 0 | AF5: golpe de sol | AG5: 8 | AH5: =+IFERROR((BD_MR_RF[[#This Row],[Valor Extra 1]]/BD_MR_RF[[#This Row],[Muestra]]),"0") -> 0.008 | AJ5: 0 | AK5: =+IFERROR((BD_MR_RF[[#This Row],[Valor Extra 2]]/BD_MR_RF[[#This Row],[Muestra]]),"0") -> 0 | AL5: 0 | AM5: =+IFERROR((BD_MR_RF[[#This Row],[Calibre >16]]/BD_MR_RF[[#This Row],[Muestra]]),"0") -> 0 | AN5: 0 | AO5: =+IFERROR((BD_MR_RF[[#This Row],[Calibre <16]]/BD_MR_RF[[#This Row],[Muestra]]),"0") -> 0 | AP5: S/A | AQ5: S/A | AR5: S/A | AS5: S/A | AT5: S/A | AU5: S/A | AV5: S/A | AW5: 14.8 | AX5: C | AY5: C | AZ5: =SUM(BD_MR_RF[[#This Row],[Desviación de Color]]+BD_MR_RF[[#This Row],[Sobremaduro]]+BD_MR_RF[[#This Row],[Daño Mécanico]]+BD_MR_RF[[#This Row],[Daño Insecto]]+BD_MR_RF[[#This Row],[Block]]+BD_MR_RF[[#This Row],[Mohos]]) -> 139 | BA5: =SUM(BD_MR_RF[[#This Row],[% Desv. Color (≤5%)]]+BD_MR_RF[[#This Row],[% Sobremaduro (≤6%)]]+BD_MR_RF[[#This Row],[% Daño Mécanico (≤6%)]]+BD_MR_RF[[#This Row],[% Daño Insc. (≤5%)]]+BD_MR_RF[[#This Row],[% Block (≤5%)]]+BD_MR_RF[[#This Row],[% Mohos (0%)]]) -> 0.139 | BB5: S/O | BC5: =1-BD_MR_RF[[#This Row],[% Defectos]] -> 0.861 | BD5: Benjamin Navarro | BE5: =SUM(BD_MR_RF[[#This Row],[Palos (Un.) (≤18)]:[Larvas (Un.) (≤24)]]) -> 0 | BF5: =SUM(BD_MR_RF[[#This Row],[Vidrio (Un.) (0)]:[Plástico (Un.) (0)]]) -> 0 | BG5: =IF(ISBLANK(BD_MR_RF[[#This Row],[Descripción del Producto]]),"",BD_MR_RF[[#This Row],[Descripción del Producto]]) -> MO S/V Org. S/C PSP 12 kg en Caja | BH5: =IF(ISBLANK(BD_MR_RF[[#This Row],[N° Lote]]),"",BD_MR_RF[[#This Row],[N° Lote]]) -> 7830 | BI5: =IF(ISBLANK(BD_MR_RF[[#This Row],[N° Pallet]]),"",BD_MR_RF[[#This Row],[N° Pallet]]) -> 21221
A6: 46037 | B6: =_xlfn.ISOWEEKNUM(BD_MR_RF[[#This Row],[Fecha]]) -> 3 | C6: 1 | D6: 3 | E6: 304231000 | F6: =IFERROR("" & _xlfn.XLOOKUP(BD_MR_RF[[#This Row],[Código]],BD_Cod!A:A,BD_Cod!B:B), "") -> MO S/V Org. S/C PSP 12 kg en Caja | G6: =IFERROR(" " &_xlfn.XLOOKUP(BD_MR_RF[[#This Row],[Código]],BD_Cod!A:A,BD_Cod!H:H," ")," ") -> PSP | H6: 21221 | I6: 7830 | J6: 1000 | K6: 0.39375 | L6: N/A | M6: 12550 | N6: -10.1 | O6: C | P6: C | Q6: =1-BD_MR_RF[[#This Row],[% Defectos]] -> 0.902 | R6: 23 | S6: =+IFERROR((BD_MR_RF[[#This Row],[Desviación de Color]]/BD_MR_RF[[#This Row],[Muestra]]),"0") -> 0.023 | T6: 0 | U6: =+IFERROR((BD_MR_RF[[#This Row],[Sobremaduro]]/BD_MR_RF[[#This Row],[Muestra]]),"0") -> 0 | V6: 4 | W6: =+IFERROR((BD_MR_RF[[#This Row],[Daño Mécanico]]/BD_MR_RF[[#This Row],[Muestra]]),"0") -> 0.004 | X6: 26 | Y6: =+IFERROR((BD_MR_RF[[#This Row],[Daño Insecto]]/BD_MR_RF[[#This Row],[Muestra]]),"0") -> 0.026 | Z6: 0 | AA6: =+IFERROR((BD_MR_RF[[#This Row],[Block]]/BD_MR_RF[[#This Row],[Muestra]]),"0") -> 0 | AB6: 45 | AC6: =+IFERROR((BD_MR_RF[[#This Row],[Mohos]]/BD_MR_RF[[#This Row],[Muestra]]),"0") -> 0.045 | AD6: 5 | AE6: 0 | AF6: aplastado | AG6: 5 | AH6: =+IFERROR((BD_MR_RF[[#This Row],[Valor Extra 1]]/BD_MR_RF[[#This Row],[Muestra]]),"0") -> 0.005 | AJ6: 0 | AK6: =+IFERROR((BD_MR_RF[[#This Row],[Valor Extra 2]]/BD_MR_RF[[#This Row],[Muestra]]),"0") -> 0 | AL6: 0 | AM6: =+IFERROR((BD_MR_RF[[#This Row],[Calibre >16]]/BD_MR_RF[[#This Row],[Muestra]]),"0") -> 0 | AN6: 0 | AO6: =+IFERROR((BD_MR_RF[[#This Row],[Calibre <16]]/BD_MR_RF[[#This Row],[Muestra]]),"0") -> 0 | AP6: S/A | AQ6: S/A | AR6: S/A | AS6: S/A | AT6: S/A | AU6: S/A | AV6: S/A | AW6: 13.6 | AX6: C | AY6: C | AZ6: =SUM(BD_MR_RF[[#This Row],[Desviación de Color]]+BD_MR_RF[[#This Row],[Sobremaduro]]+BD_MR_RF[[#This Row],[Daño Mécanico]]+BD_MR_RF[[#This Row],[Daño Insecto]]+BD_MR_RF[[#This Row],[Block]]+BD_MR_RF[[#This Row],[Mohos]]) -> 98 | BA6: =SUM(BD_MR_RF[[#This Row],[% Desv. Color (≤5%)]]+BD_MR_RF[[#This Row],[% Sobremaduro (≤6%)]]+BD_MR_RF[[#This Row],[% Daño Mécanico (≤6%)]]+BD_MR_RF[[#This Row],[% Daño Insc. (≤5%)]]+BD_MR_RF[[#This Row],[% Block (≤5%)]]+BD_MR_RF[[#This Row],[% Mohos (0%)]]) -> 0.098 | BB6: S/O | BC6: =1-BD_MR_RF[[#This Row],[% Defectos]] -> 0.902 | BD6: Benjamin Navarro | BE6: =SUM(BD_MR_RF[[#This Row],[Palos (Un.) (≤18)]:[Larvas (Un.) (≤24)]]) -> 0 | BF6: =SUM(BD_MR_RF[[#This Row],[Vidrio (Un.) (0)]:[Plástico (Un.) (0)]]) -> 0 | BG6: =IF(ISBLANK(BD_MR_RF[[#This Row],[Descripción del Producto]]),"",BD_MR_RF[[#This Row],[Descripción del Producto]]) -> MO S/V Org. S/C PSP 12 kg en Caja | BH6: =IF(ISBLANK(BD_MR_RF[[#This Row],[N° Lote]]),"",BD_MR_RF[[#This Row],[N° Lote]]) -> 7830 | BI6: =IF(ISBLANK(BD_MR_RF[[#This Row],[N° Pallet]]),"",BD_MR_RF[[#This Row],[N° Pallet]]) -> 21221
A7: 46037 | B7: =_xlfn.ISOWEEKNUM(BD_MR_RF[[#This Row],[Fecha]]) -> 3 | C7: 1 | D7: 3 | E7: 304231000 | F7: =IFERROR("" & _xlfn.XLOOKUP(BD_MR_RF[[#This Row],[Código]],BD_Cod!A:A,BD_Cod!B:B), "") -> MO S/V Org. S/C PSP 12 kg en Caja | G7: =IFERROR(" " &_xlfn.XLOOKUP(BD_MR_RF[[#This Row],[Código]],BD_Cod!A:A,BD_Cod!H:H," ")," ") -> PSP | H7: 21222 | I7: 7830 | J7: 1000 | K7: 0.4 | L7: N/A | M7: 12555 | N7: -12.1 | O7: C | P7: C | Q7: =1-BD_MR_RF[[#This Row],[% Defectos]] -> 0.827 | R7: 32 | S7: =+IFERROR((BD_MR_RF[[#This Row],[Desviación de Color]]/BD_MR_RF[[#This Row],[Muestra]]),"0") -> 0.032 | T7: 0 | U7: =+IFERROR((BD_MR_RF[[#This Row],[Sobremaduro]]/BD_MR_RF[[#This Row],[Muestra]]),"0") -> 0 | V7: 9 | W7: =+IFERROR((BD_MR_RF[[#This Row],[Daño Mécanico]]/BD_MR_RF[[#This Row],[Muestra]]),"0") -> 0.009 | X7: 98 | Y7: =+IFERROR((BD_MR_RF[[#This Row],[Daño Insecto]]/BD_MR_RF[[#This Row],[Muestra]]),"0") -> 0.098 | Z7: 34 | AA7: =+IFERROR((BD_MR_RF[[#This Row],[Block]]/BD_MR_RF[[#This Row],[Muestra]]),"0") -> 0.034 | AB7: 0 | AC7: =+IFERROR((BD_MR_RF[[#This Row],[Mohos]]/BD_MR_RF[[#This Row],[Muestra]]),"0") -> 0 | AD7: 1 | AE7: 0 | AG7: 0 | AH7: =+IFERROR((BD_MR_RF[[#This Row],[Valor Extra 1]]/BD_MR_RF[[#This Row],[Muestra]]),"0") -> 0 | AJ7: 0 | AK7: =+IFERROR((BD_MR_RF[[#This Row],[Valor Extra 2]]/BD_MR_RF[[#This Row],[Muestra]]),"0") -> 0 | AL7: 0 | AM7: =+IFERROR((BD_MR_RF[[#This Row],[Calibre >16]]/BD_MR_RF[[#This Row],[Muestra]]),"0") -> 0 | AN7: 0 | AO7: =+IFERROR((BD_MR_RF[[#This Row],[Calibre <16]]/BD_MR_RF[[#This Row],[Muestra]]),"0") -> 0 | AP7: S/A | AQ7: S/A | AR7: S/A | AS7: S/A | AT7: S/A | AU7: S/A | AV7: S/A | AW7: 13.5 | AX7: C | AY7: C | AZ7: =SUM(BD_MR_RF[[#This Row],[Desviación de Color]]+BD_MR_RF[[#This Row],[Sobremaduro]]+BD_MR_RF[[#This Row],[Daño Mécanico]]+BD_MR_RF[[#This Row],[Daño Insecto]]+BD_MR_RF[[#This Row],[Block]]+BD_MR_RF[[#This Row],[Mohos]]) -> 173 | BA7: =SUM(BD_MR_RF[[#This Row],[% Desv. Color (≤5%)]]+BD_MR_RF[[#This Row],[% Sobremaduro (≤6%)]]+BD_MR_RF[[#This Row],[% Daño Mécanico (≤6%)]]+BD_MR_RF[[#This Row],[% Daño Insc. (≤5%)]]+BD_MR_RF[[#This Row],[% Block (≤5%)]]+BD_MR_RF[[#This Row],[% Mohos (0%)]]) -> 0.173 | BB7: S/O | BC7: =1-BD_MR_RF[[#This Row],[% Defectos]] -> 0.827 | BD7: Fernanda Delgado | BE7: =SUM(BD_MR_RF[[#This Row],[Palos (Un.) (≤18)]:[Larvas (Un.) (≤24)]]) -> 0 | BF7: =SUM(BD_MR_RF[[#This Row],[Vidrio (Un.) (0)]:[Plástico (Un.) (0)]]) -> 0 | BG7: =IF(ISBLANK(BD_MR_RF[[#This Row],[Descripción del Producto]]),"",BD_MR_RF[[#This Row],[Descripción del Producto]]) -> MO S/V Org. S/C PSP 12 kg en Caja | BH7: =IF(ISBLANK(BD_MR_RF[[#This Row],[N° Lote]]),"",BD_MR_RF[[#This Row],[N° Lote]]) -> 7830 | BI7: =IF(ISBLANK(BD_MR_RF[[#This Row],[N° Pallet]]),"",BD_MR_RF[[#This Row],[N° Pallet]]) -> 21222
A8: 46037 | B8: =_xlfn.ISOWEEKNUM(BD_MR_RF[[#This Row],[Fecha]]) -> 3 | C8: 1 | D8: 3 | E8: 304231000 | F8: =IFERROR("" & _xlfn.XLOOKUP(BD_MR_RF[[#This Row],[Código]],BD_Cod!A:A,BD_Cod!B:B), "") -> MO S/V Org. S/C PSP 12 kg en Caja | G8: =IFERROR(" " &_xlfn.XLOOKUP(BD_MR_RF[[#This Row],[Código]],BD_Cod!A:A,BD_Cod!H:H," ")," ") -> PSP | H8: 21222 | I8: 7830 | J8: 1000 | K8: 0.40833333 | L8: N/A | M8: 12565 | N8: -11.6 | O8: C | P8: C | Q8: =1-BD_MR_RF[[#This Row],[% Defectos]] -> 0.913 | R8: 84 | S8: =+IFERROR((BD_MR_RF[[#This Row],[Desviación de Color]]/BD_MR_RF[[#This Row],[Muestra]]),"0") -> 0.084 | T8: 0 | U8: =+IFERROR((BD_MR_RF[[#This Row],[Sobremaduro]]/BD_MR_RF[[#This Row],[Muestra]]),"0") -> 0 | V8: 0 | W8: =+IFERROR((BD_MR_RF[[#This Row],[Daño Mécanico]]/BD_MR_RF[[#This Row],[Muestra]]),"0") -> 0 | X8: 3 | Y8: =+IFERROR((BD_MR_RF[[#This Row],[Daño Insecto]]/BD_MR_RF[[#This Row],[Muestra]]),"0") -> 0.003 | Z8: 0 | AA8: =+IFERROR((BD_MR_RF[[#This Row],[Block]]/BD_MR_RF[[#This Row],[Muestra]]),"0") -> 0 | AB8: 0 | AC8: =+IFERROR((BD_MR_RF[[#This Row],[Mohos]]/BD_MR_RF[[#This Row],[Muestra]]),"0") -> 0 | AD8: 2 | AE8: 0 | AF8: aplastado | AG8: 15 | AH8: =+IFERROR((BD_MR_RF[[#This Row],[Valor Extra 1]]/BD_MR_RF[[#This Row],[Muestra]]),"0") -> 0.015 | AJ8: 0 | AK8: =+IFERROR((BD_MR_RF[[#This Row],[Valor Extra 2]]/BD_MR_RF[[#This Row],[Muestra]]),"0") -> 0 | AL8: 0 | AM8: =+IFERROR((BD_MR_RF[[#This Row],[Calibre >16]]/BD_MR_RF[[#This Row],[Muestra]]),"0") -> 0 | AN8: 0 | AO8: =+IFERROR((BD_MR_RF[[#This Row],[Calibre <16]]/BD_MR_RF[[#This Row],[Muestra]]),"0") -> 0 | AP8: S/A | AQ8: S/A | AR8: S/A | AS8: S/A | AT8: S/A | AU8: S/A | AV8: S/A | AW8: 13.8 | AX8: C | AY8: C | AZ8: =SUM(BD_MR_RF[[#This Row],[Desviación de Color]]+BD_MR_RF[[#This Row],[Sobremaduro]]+BD_MR_RF[[#This Row],[Daño Mécanico]]+BD_MR_RF[[#This Row],[Daño Insecto]]+BD_MR_RF[[#This Row],[Block]]+BD_MR_RF[[#This Row],[Mohos]]) -> 87 | BA8: =SUM(BD_MR_RF[[#This Row],[% Desv. Color (≤5%)]]+BD_MR_RF[[#This Row],[% Sobremaduro (≤6%)]]+BD_MR_RF[[#This Row],[% Daño Mécanico (≤6%)]]+BD_MR_RF[[#This Row],[% Daño Insc. (≤5%)]]+BD_MR_RF[[#This Row],[% Block (≤5%)]]+BD_MR_RF[[#This Row],[% Mohos (0%)]]) -> 0.087 | BB8: S/O | BC8: =1-BD_MR_RF[[#This Row],[% Defectos]] -> 0.913 | BD8: Fernanda Delgado | BE8: =SUM(BD_MR_RF[[#This Row],[Palos (Un.) (≤18)]:[Larvas (Un.) (≤24)]]) -> 0 | BF8: =SUM(BD_MR_RF[[#This Row],[Vidrio (Un.) (0)]:[Plástico (Un.) (0)]]) -> 0 | BG8: =IF(ISBLANK(BD_MR_RF[[#This Row],[Descripción del Producto]]),"",BD_MR_RF[[#This Row],[Descripción del Producto]]) -> MO S/V Org. S/C PSP 12 kg en Caja | BH8: =IF(ISBLANK(BD_MR_RF[[#This Row],[N° Lote]]),"",BD_MR_RF[[#This Row],[N° Lote]]) -> 7830 | BI8: =IF(ISBLANK(BD_MR_RF[[#This Row],[N° Pallet]]),"",BD_MR_RF[[#This Row],[N° Pallet]]) -> 21222
A9: 46037 | B9: =_xlfn.ISOWEEKNUM(BD_MR_RF[[#This Row],[Fecha]]) -> 3 | C9: 1 | D9: 3 | E9: 304231000 | F9: =IFERROR("" & _xlfn.XLOOKUP(BD_MR_RF[[#This Row],[Código]],BD_Cod!A:A,BD_Cod!B:B), "") -> MO S/V Org. S/C PSP 12 kg en Caja | G9: =IFERROR(" " &_xlfn.XLOOKUP(BD_MR_RF[[#This Row],[Código]],BD_Cod!A:A,BD_Cod!H:H," ")," ") -> PSP | H9: 21223 | I9: 7830 | J9: 1000 | K9: 0.42291667 | L9: N/A | M9: 12515 | N9: -10.8 | O9: C | P9: C | Q9: =1-BD_MR_RF[[#This Row],[% Defectos]] -> 0.913 | R9: 34 | S9: =+IFERROR((BD_MR_RF[[#This Row],[Desviación de Color]]/BD_MR_RF[[#This Row],[Muestra]]),"0") -> 0.034 | T9: 0 | U9: =+IFERROR((BD_MR_RF[[#This Row],[Sobremaduro]]/BD_MR_RF[[#This Row],[Muestra]]),"0") -> 0 | V9: 0 | W9: =+IFERROR((BD_MR_RF[[#This Row],[Daño Mécanico]]/BD_MR_RF[[#This Row],[Muestra]]),"0") -> 0 | X9: 49 | Y9: =+IFERROR((BD_MR_RF[[#This Row],[Daño Insecto]]/BD_MR_RF[[#This Row],[Muestra]]),"0") -> 0.049 | Z9: 0 | AA9: =+IFERROR((BD_MR_RF[[#This Row],[Block]]/BD_MR_RF[[#This Row],[Muestra]]),"0") -> 0 | AB9: 4 | AC9: =+IFERROR((BD_MR_RF[[#This Row],[Mohos]]/BD_MR_RF[[#This Row],[Muestra]]),"0") -> 0.004 | AD9: 6 | AE9: 0 | AG9: 0 | AH9: =+IFERROR((BD_MR_RF[[#This Row],[Valor Extra 1]]/BD_MR_RF[[#This Row],[Muestra]]),"0") -> 0 | AJ9: 0 | AK9: =+IFERROR((BD_MR_RF[[#This Row],[Valor Extra 2]]/BD_MR_RF[[#This Row],[Muestra]]),"0") -> 0 | AL9: 0 | AM9: =+IFERROR((BD_MR_RF[[#This Row],[Calibre >16]]/BD_MR_RF[[#This Row],[Muestra]]),"0") -> 0 | AN9: 0 | AO9: =+IFERROR((BD_MR_RF[[#This Row],[Calibre <16]]/BD_MR_RF[[#This Row],[Muestra]]),"0") -> 0 | AP9: S/A | AQ9: S/A | AR9: S/A | AS9: S/A | AT9: S/A | AU9: S/A | AV9: S/A | AW9: 14.8 | AX9: C | AY9: C | AZ9: =SUM(BD_MR_RF[[#This Row],[Desviación de Color]]+BD_MR_RF[[#This Row],[Sobremaduro]]+BD_MR_RF[[#This Row],[Daño Mécanico]]+BD_MR_RF[[#This Row],[Daño Insecto]]+BD_MR_RF[[#This Row],[Block]]+BD_MR_RF[[#This Row],[Mohos]]) -> 87 | BA9: =SUM(BD_MR_RF[[#This Row],[% Desv. Color (≤5%)]]+BD_MR_RF[[#This Row],[% Sobremaduro (≤6%)]]+BD_MR_RF[[#This Row],[% Daño Mécanico (≤6%)]]+BD_MR_RF[[#This Row],[% Daño Insc. (≤5%)]]+BD_MR_RF[[#This Row],[% Block (≤5%)]]+BD_MR_RF[[#This Row],[% Mohos (0%)]]) -> 0.087 | BB9: S/O | BC9: =1-BD_MR_RF[[#This Row],[% Defectos]] -> 0.913 | BD9: Fernanda Delgado | BE9: =SUM(BD_MR_RF[[#This Row],[Palos (Un.) (≤18)]:[Larvas (Un.) (≤24)]]) -> 0 | BF9: =SUM(BD_MR_RF[[#This Row],[Vidrio (Un.) (0)]:[Plástico (Un.) (0)]]) -> 0 | BG9: =IF(ISBLANK(BD_MR_RF[[#This Row],[Descripción del Producto]]),"",BD_MR_RF[[#This Row],[Descripción del Producto]]) -> MO S/V Org. S/C PSP 12 kg en Caja | BH9: =IF(ISBLANK(BD_MR_RF[[#This Row],[N° Lote]]),"",BD_MR_RF[[#This Row],[N° Lote]]) -> 7830 | BI9: =IF(ISBLANK(BD_MR_RF[[#This Row],[N° Pallet]]),"",BD_MR_RF[[#This Row],[N° Pallet]]) -> 21223
A10: 46037 | B10: =_xlfn.ISOWEEKNUM(BD_MR_RF[[#This Row],[Fecha]]) -> 3 | C10: 1 | D10: 3 | E10: 304231000 | F10: =IFERROR("" & _xlfn.XLOOKUP(BD_MR_RF[[#This Row],[Código]],BD_Cod!A:A,BD_Cod!B:B), "") -> MO S/V Org. S/C PSP 12 kg en Caja | G10: =IFERROR(" " &_xlfn.XLOOKUP(BD_MR_RF[[#This Row],[Código]],BD_Cod!A:A,BD_Cod!H:H," ")," ") -> PSP | H10: 21250 | I10: 7830 | J10: 1000 | K10: 0.43680556 | L10: N/A | M10: 12565 | N10: -11.6 | O10: C | P10: C | Q10: =1-BD_MR_RF[[#This Row],[% Defectos]] -> 0.933 | R10: 33 | S10: =+IFERROR((BD_MR_RF[[#This Row],[Desviación de Color]]/BD_MR_RF[[#This Row],[Muestra]]),"0") -> 0.033 | T10: 0 | U10: =+IFERROR((BD_MR_RF[[#This Row],[Sobremaduro]]/BD_MR_RF[[#This Row],[Muestra]]),"0") -> 0 | V10: 0 | W10: =+IFERROR((BD_MR_RF[[#This Row],[Daño Mécanico]]/BD_MR_RF[[#This Row],[Muestra]]),"0") -> 0 | X10: 34 | Y10: =+IFERROR((BD_MR_RF[[#This Row],[Daño Insecto]]/BD_MR_RF[[#This Row],[Muestra]]),"0") -> 0.034 | Z10: 0 | AA10: =+IFERROR((BD_MR_RF[[#This Row],[Block]]/BD_MR_RF[[#This Row],[Muestra]]),"0") -> 0 | AB10: 0 | AC10: =+IFERROR((BD_MR_RF[[#This Row],[Mohos]]/BD_MR_RF[[#This Row],[Muestra]]),"0") -> 0 | AD10: 0 | AE10: 0 | AG10: 0 | AH10: =+IFERROR((BD_MR_RF[[#This Row],[Valor Extra 1]]/BD_MR_RF[[#This Row],[Muestra]]),"0") -> 0 | AJ10: 0 | AK10: =+IFERROR((BD_MR_RF[[#This Row],[Valor Extra 2]]/BD_MR_RF[[#This Row],[Muestra]]),"0") -> 0 | AL10: 0 | AM10: =+IFERROR((BD_MR_RF[[#This Row],[Calibre >16]]/BD_MR_RF[[#This Row],[Muestra]]),"0") -> 0 | AN10: 0 | AO10: =+IFERROR((BD_MR_RF[[#This Row],[Calibre <16]]/BD_MR_RF[[#This Row],[Muestra]]),"0") -> 0 | AP10: S/A | AQ10: S/A | AR10: S/A | AS10: S/A | AT10: S/A | AU10: S/A | AV10: S/A | AW10: 16.1 | AX10: C | AY10: C | AZ10: =SUM(BD_MR_RF[[#This Row],[Desviación de Color]]+BD_MR_RF[[#This Row],[Sobremaduro]]+BD_MR_RF[[#This Row],[Daño Mécanico]]+BD_MR_RF[[#This Row],[Daño Insecto]]+BD_MR_RF[[#This Row],[Block]]+BD_MR_RF[[#This Row],[Mohos]]) -> 67 | BA10: =SUM(BD_MR_RF[[#This Row],[% Desv. Color (≤5%)]]+BD_MR_RF[[#This Row],[% Sobremaduro (≤6%)]]+BD_MR_RF[[#This Row],[% Daño Mécanico (≤6%)]]+BD_MR_RF[[#This Row],[% Daño Insc. (≤5%)]]+BD_MR_RF[[#This Row],[% Block (≤5%)]]+BD_MR_RF[[#This Row],[% Mohos (0%)]]) -> 0.067 | BB10: S/O | BC10: =1-BD_MR_RF[[#This Row],[% Defectos]] -> 0.933 | BD10: Fernanda Delgado | BE10: =SUM(BD_MR_RF[[#This Row],[Palos (Un.) (≤18)]:[Larvas (Un.) (≤24)]]) -> 0 | BF10: =SUM(BD_MR_RF[[#This Row],[Vidrio (Un.) (0)]:[Plástico (Un.) (0)]]) -> 0 | BG10: =IF(ISBLANK(BD_MR_RF[[#This Row],[Descripción del Producto]]),"",BD_MR_RF[[#This Row],[Descripción del Producto]]) -> MO S/V Org. S/C PSP 12 kg en Caja | BH10: =IF(ISBLANK(BD_MR_RF[[#This Row],[N° Lote]]),"",BD_MR_RF[[#This Row],[N° Lote]]) -> 7830 | BI10: =IF(ISBLANK(BD_MR_RF[[#This Row],[N° Pallet]]),"",BD_MR_RF[[#This Row],[N° Pallet]]) -> 21250
A11: 46037 | B11: =_xlfn.ISOWEEKNUM(BD_MR_RF[[#This Row],[Fecha]]) -> 3 | C11: 1 | D11: 3 | E11: 304231000 | F11: =IFERROR("" & _xlfn.XLOOKUP(BD_MR_RF[[#This Row],[Código]],BD_Cod!A:A,BD_Cod!B:B), "") -> MO S/V Org. S/C PSP 12 kg en Caja | G11: =IFERROR(" " &_xlfn.XLOOKUP(BD_MR_RF[[#This Row],[Código]],BD_Cod!A:A,BD_Cod!H:H," ")," ") -> PSP | H11: 21250 | I11: 7830 | J11: 1000 | K11: 0.44027778 | L11: N/A | M11: 12575 | N11: -10.4 | O11: C | P11: C | Q11: =1-BD_MR_RF[[#This Row],[% Defectos]] -> 0.855 | R11: 54 | S11: =+IFERROR((BD_MR_RF[[#This Row],[Desviación de Color]]/BD_MR_RF[[#This Row],[Muestra]]),"0") -> 0.054 | T11: 0 | U11: =+IFERROR((BD_MR_RF[[#This Row],[Sobremaduro]]/BD_MR_RF[[#This Row],[Muestra]]),"0") -> 0 | V11: 0 | W11: =+IFERROR((BD_MR_RF[[#This Row],[Daño Mécanico]]/BD_MR_RF[[#This Row],[Muestra]]),"0") -> 0 | X11: 77 | Y11: =+IFERROR((BD_MR_RF[[#This Row],[Daño Insecto]]/BD_MR_RF[[#This Row],[Muestra]]),"0") -> 0.077 | Z11: 14 | AA11: =+IFERROR((BD_MR_RF[[#This Row],[Block]]/BD_MR_RF[[#This Row],[Muestra]]),"0") -> 0.014 | AB11: 0 | AC11: =+IFERROR((BD_MR_RF[[#This Row],[Mohos]]/BD_MR_RF[[#This Row],[Muestra]]),"0") -> 0 | AD11: 1 | AE11: 0 | AG11: 0 | AH11: =+IFERROR((BD_MR_RF[[#This Row],[Valor Extra 1]]/BD_MR_RF[[#This Row],[Muestra]]),"0") -> 0 | AJ11: 0 | AK11: =+IFERROR((BD_MR_RF[[#This Row],[Valor Extra 2]]/BD_MR_RF[[#This Row],[Muestra]]),"0") -> 0 | AL11: 0 | AM11: =+IFERROR((BD_MR_RF[[#This Row],[Calibre >16]]/BD_MR_RF[[#This Row],[Muestra]]),"0") -> 0 | AN11: 0 | AO11: =+IFERROR((BD_MR_RF[[#This Row],[Calibre <16]]/BD_MR_RF[[#This Row],[Muestra]]),"0") -> 0 | AP11: S/A | AQ11: S/A | AR11: S/A | AS11: S/A | AT11: S/A | AU11: S/A | AV11: S/A | AW11: 13.6 | AX11: C | AY11: C | AZ11: =SUM(BD_MR_RF[[#This Row],[Desviación de Color]]+BD_MR_RF[[#This Row],[Sobremaduro]]+BD_MR_RF[[#This Row],[Daño Mécanico]]+BD_MR_RF[[#This Row],[Daño Insecto]]+BD_MR_RF[[#This Row],[Block]]+BD_MR_RF[[#This Row],[Mohos]]) -> 145 | BA11: =SUM(BD_MR_RF[[#This Row],[% Desv. Color (≤5%)]]+BD_MR_RF[[#This Row],[% Sobremaduro (≤6%)]]+BD_MR_RF[[#This Row],[% Daño Mécanico (≤6%)]]+BD_MR_RF[[#This Row],[% Daño Insc. (≤5%)]]+BD_MR_RF[[#This Row],[% Block (≤5%)]]+BD_MR_RF[[#This Row],[% Mohos (0%)]]) -> 0.145 | BB11: S/O | BC11: =1-BD_MR_RF[[#This Row],[% Defectos]] -> 0.855 | BD11: Fernanda Delgado | BE11: =SUM(BD_MR_RF[[#This Row],[Palos (Un.) (≤18)]:[Larvas (Un.) (≤24)]]) -> 0 | BF11: =SUM(BD_MR_RF[[#This Row],[Vidrio (Un.) (0)]:[Plástico (Un.) (0)]]) -> 0 | BG11: =IF(ISBLANK(BD_MR_RF[[#This Row],[Descripción del Producto]]),"",BD_MR_RF[[#This Row],[Descripción del Producto]]) -> MO S/V Org. S/C PSP 12 kg en Caja | BH11: =IF(ISBLANK(BD_MR_RF[[#This Row],[N° Lote]]),"",BD_MR_RF[[#This Row],[N° Lote]]) -> 7830 | BI11: =IF(ISBLANK(BD_MR_RF[[#This Row],[N° Pallet]]),"",BD_MR_RF[[#This Row],[N° Pallet]]) -> 21250
A12: 46037 | B12: =_xlfn.ISOWEEKNUM(BD_MR_RF[[#This Row],[Fecha]]) -> 3 | C12: 1 | D12: 3 | E12: 304231000 | F12: =IFERROR("" & _xlfn.XLOOKUP(BD_MR_RF[[#This Row],[Código]],BD_Cod!A:A,BD_Cod!B:B), "") -> MO S/V Org. S/C PSP 12 kg en Caja | G12: =IFERROR(" " &_xlfn.XLOOKUP(BD_MR_RF[[#This Row],[Código]],BD_Cod!A:A,BD_Cod!H:H," ")," ") -> PSP | H12: 21251 | I12: 7830 | J12: 1000 | K12: 0.45555556 | L12: N/A | M12: 12560 | N12: -14 | O12: C | P12: C | Q12: =1-BD_MR_RF[[#This Row],[% Defectos]] -> 0.923 | R12: 70 | S12: =+IFERROR((BD_MR_RF[[#This Row],[Desviación de Color]]/BD_MR_RF[[#This Row],[Muestra]]),"0") -> 0.07 | T12: 0 | U12: =+IFERROR((BD_MR_RF[[#This Row],[Sobremaduro]]/BD_MR_RF[[#This Row],[Muestra]]),"0") -> 0 | V12: 0 | W12: =+IFERROR((BD_MR_RF[[#This Row],[Daño Mécanico]]/BD_MR_RF[[#This Row],[Muestra]]),"0") -> 0 | X12: 7 | Y12: =+IFERROR((BD_MR_RF[[#This Row],[Daño Insecto]]/BD_MR_RF[[#This Row],[Muestra]]),"0") -> 0.007 | Z12: 0 | AA12: =+IFERROR((BD_MR_RF[[#This Row],[Block]]/BD_MR_RF[[#This Row],[Muestra]]),"0") -> 0 | AB12: 0 | AC12: =+IFERROR((BD_MR_RF[[#This Row],[Mohos]]/BD_MR_RF[[#This Row],[Muestra]]),"0") -> 0 | AD12: 0 | AE12: 0 | AG12: 0 | AH12: =+IFERROR((BD_MR_RF[[#This Row],[Valor Extra 1]]/BD_MR_RF[[#This Row],[Muestra]]),"0") -> 0 | AJ12: 0 | AK12: =+IFERROR((BD_MR_RF[[#This Row],[Valor Extra 2]]/BD_MR_RF[[#This Row],[Muestra]]),"0") -> 0 | AL12: 0 | AM12: =+IFERROR((BD_MR_RF[[#This Row],[Calibre >16]]/BD_MR_RF[[#This Row],[Muestra]]),"0") -> 0 | AN12: 0 | AO12: =+IFERROR((BD_MR_RF[[#This Row],[Calibre <16]]/BD_MR_RF[[#This Row],[Muestra]]),"0") -> 0 | AP12: S/A | AQ12: S/A | AR12: S/A | AS12: S/A | AT12: S/A | AU12: S/A | AV12: S/A | AW12: 15.4 | AX12: C | AY12: C | AZ12: =SUM(BD_MR_RF[[#This Row],[Desviación de Color]]+BD_MR_RF[[#This Row],[Sobremaduro]]+BD_MR_RF[[#This Row],[Daño Mécanico]]+BD_MR_RF[[#This Row],[Daño Insecto]]+BD_MR_RF[[#This Row],[Block]]+BD_MR_RF[[#This Row],[Mohos]]) -> 77 | BA12: =SUM(BD_MR_RF[[#This Row],[% Desv. Color (≤5%)]]+BD_MR_RF[[#This Row],[% Sobremaduro (≤6%)]]+BD_MR_RF[[#This Row],[% Daño Mécanico (≤6%)]]+BD_MR_RF[[#This Row],[% Daño Insc. (≤5%)]]+BD_MR_RF[[#This Row],[% Block (≤5%)]]+BD_MR_RF[[#This Row],[% Mohos (0%)]]) -> 0.077 | BB12: S/O | BC12: =1-BD_MR_RF[[#This Row],[% Defectos]] -> 0.923 | BD12: Benjamin Navarro | BE12: =SUM(BD_MR_RF[[#This Row],[Palos (Un.) (≤18)]:[Larvas (Un.) (≤24)]]) -> 0 | BF12: =SUM(BD_MR_RF[[#This Row],[Vidrio (Un.) (0)]:[Plástico (Un.) (0)]]) -> 0 | BG12: =IF(ISBLANK(BD_MR_RF[[#This Row],[Descripción del Producto]]),"",BD_MR_RF[[#This Row],[Descripción del Producto]]) -> MO S/V Org. S/C PSP 12 kg en Caja | BH12: =IF(ISBLANK(BD_MR_RF[[#This Row],[N° Lote]]),"",BD_MR_RF[[#This Row],[N° Lote]]) -> 7830 | BI12: =IF(ISBLANK(BD_MR_RF[[#This Row],[N° Pallet]]),"",BD_MR_RF[[#This Row],[N° Pallet]]) -> 21251
A13: 46037 | B13: =_xlfn.ISOWEEKNUM(BD_MR_RF[[#This Row],[Fecha]]) -> 3 | C13: 1 | D13: 3 | E13: 304231000 | F13: =IFERROR("" & _xlfn.XLOOKUP(BD_MR_RF[[#This Row],[Código]],BD_Cod!A:A,BD_Cod!B:B), "") -> MO S/V Org. S/C PSP 12 kg en Caja | G13: =IFERROR(" " &_xlfn.XLOOKUP(BD_MR_RF[[#This Row],[Código]],BD_Cod!A:A,BD_Cod!H:H," ")," ") -> PSP | H13: 21252 | I13: 7830 | J13: 1000 | K13: 0.46736111 | L13: N/A | M13: 12575 | N13: -14 | O13: C | P13: C | Q13: =1-BD_MR_RF[[#This Row],[% Defectos]] -> 0.934 | R13: 6 | S13: =+IFERROR((BD_MR_RF[[#This Row],[Desviación de Color]]/BD_MR_RF[[#This Row],[Muestra]]),"0") -> 0.006 | T13: 0 | U13: =+IFERROR((BD_MR_RF[[#This Row],[Sobremaduro]]/BD_MR_RF[[#This Row],[Muestra]]),"0") -> 0 | V13: 0 | W13: =+IFERROR((BD_MR_RF[[#This Row],[Daño Mécanico]]/BD_MR_RF[[#This Row],[Muestra]]),"0") -> 0 | X13: 60 | Y13: =+IFERROR((BD_MR_RF[[#This Row],[Daño Insecto]]/BD_MR_RF[[#This Row],[Muestra]]),"0") -> 0.06 | Z13: 0 | AA13: =+IFERROR((BD_MR_RF[[#This Row],[Block]]/BD_MR_RF[[#This Row],[Muestra]]),"0") -> 0 | AB13: 0 | AC13: =+IFERROR((BD_MR_RF[[#This Row],[Mohos]]/BD_MR_RF[[#This Row],[Muestra]]),"0") -> 0 | AD13: 2 | AE13: 0 | AF13: Materia Vegetal (unid) | AG13: 1 | AJ13: 0 | AK13: =+IFERROR((BD_MR_RF[[#This Row],[Valor Extra 2]]/BD_MR_RF[[#This Row],[Muestra]]),"0") -> 0 | AL13: 0 | AM13: =+IFERROR((BD_MR_RF[[#This Row],[Calibre >16]]/BD_MR_RF[[#This Row],[Muestra]]),"0") -> 0 | AN13: 0 | AO13: =+IFERROR((BD_MR_RF[[#This Row],[Calibre <16]]/BD_MR_RF[[#This Row],[Muestra]]),"0") -> 0 | AP13: S/A | AQ13: S/A | AR13: S/A | AS13: S/A | AT13: S/A | AU13: S/A | AV13: S/A | AW13: 15.6 | AX13: C | AY13: C | AZ13: =SUM(BD_MR_RF[[#This Row],[Desviación de Color]]+BD_MR_RF[[#This Row],[Sobremaduro]]+BD_MR_RF[[#This Row],[Daño Mécanico]]+BD_MR_RF[[#This Row],[Daño Insecto]]+BD_MR_RF[[#This Row],[Block]]+BD_MR_RF[[#This Row],[Mohos]]) -> 66 | BA13: =SUM(BD_MR_RF[[#This Row],[% Desv. Color (≤5%)]]+BD_MR_RF[[#This Row],[% Sobremaduro (≤6%)]]+BD_MR_RF[[#This Row],[% Daño Mécanico (≤6%)]]+BD_MR_RF[[#This Row],[% Daño Insc. (≤5%)]]+BD_MR_RF[[#This Row],[% Block (≤5%)]]+BD_MR_RF[[#This Row],[% Mohos (0%)]]) -> 0.066 | BB13: S/O | BC13: =1-BD_MR_RF[[#This Row],[% Defectos]] -> 0.934 | BD13: Benjamin Navarro | BE13: =SUM(BD_MR_RF[[#This Row],[Palos (Un.) (≤18)]:[Larvas (Un.) (≤24)]]) -> 0 | BF13: =SUM(BD_MR_RF[[#This Row],[Vidrio (Un.) (0)]:[Plástico (Un.) (0)]]) -> 0 | BG13: =IF(ISBLANK(BD_MR_RF[[#This Row],[Descripción del Producto]]),"",BD_MR_RF[[#This Row],[Descripción del Producto]]) -> MO S/V Org. S/C PSP 12 kg en Caja | BH13: =IF(ISBLANK(BD_MR_RF[[#This Row],[N° Lote]]),"",BD_MR_RF[[#This Row],[N° Lote]]) -> 7830 | BI13: =IF(ISBLANK(BD_MR_RF[[#This Row],[N° Pallet]]),"",BD_MR_RF[[#This Row],[N° Pallet]]) -> 21252
A14: 46037 | B14: =_xlfn.ISOWEEKNUM(BD_MR_RF[[#This Row],[Fecha]]) -> 3 | C14: 1 | D14: 3 | E14: 304231000 | F14: =IFERROR("" & _xlfn.XLOOKUP(BD_MR_RF[[#This Row],[Código]],BD_Cod!A:A,BD_Cod!B:B), "") -> MO S/V Org. S/C PSP 12 kg en Caja | G14: =IFERROR(" " &_xlfn.XLOOKUP(BD_MR_RF[[#This Row],[Código]],BD_Cod!A:A,BD_Cod!H:H," ")," ") -> PSP | H14: 21253 | I14: 7830 | J14: 1000 | K14: 0.47638889 | L14: N/A | M14: 12570 | N14: -14.7 | O14: C | P14: C | Q14: =1-BD_MR_RF[[#This Row],[% Defectos]] -> 0.9 | R14: 12 | S14: =+IFERROR((BD_MR_RF[[#This Row],[Desviación de Color]]/BD_MR_RF[[#This Row],[Muestra]]),"0") -> 0.012 | T14: 0 | U14: =+IFERROR((BD_MR_RF[[#This Row],[Sobremaduro]]/BD_MR_RF[[#This Row],[Muestra]]),"0") -> 0 | V14: 0 | W14: =+IFERROR((BD_MR_RF[[#This Row],[Daño Mécanico]]/BD_MR_RF[[#This Row],[Muestra]]),"0") -> 0 | X14: 88 | Y14: =+IFERROR((BD_MR_RF[[#This Row],[Daño Insecto]]/BD_MR_RF[[#This Row],[Muestra]]),"0") -> 0.088 | Z14: 0 | AA14: =+IFERROR((BD_MR_RF[[#This Row],[Block]]/BD_MR_RF[[#This Row],[Muestra]]),"0") -> 0 | AB14: 0 | AC14: =+IFERROR((BD_MR_RF[[#This Row],[Mohos]]/BD_MR_RF[[#This Row],[Muestra]]),"0") -> 0 | AD14: 3 | AE14: 0 | AF14: Materia Vegetal (unid) | AG14: 1 | AJ14: 0 | AK14: =+IFERROR((BD_MR_RF[[#This Row],[Valor Extra 2]]/BD_MR_RF[[#This Row],[Muestra]]),"0") -> 0 | AL14: 0 | AM14: =+IFERROR((BD_MR_RF[[#This Row],[Calibre >16]]/BD_MR_RF[[#This Row],[Muestra]]),"0") -> 0 | AN14: 0 | AO14: =+IFERROR((BD_MR_RF[[#This Row],[Calibre <16]]/BD_MR_RF[[#This Row],[Muestra]]),"0") -> 0 | AP14: S/A | AQ14: S/A | AR14: S/A | AS14: S/A | AT14: S/A | AU14: S/A | AV14: S/A | AW14: 13.7 | AX14: C | AY14: C | AZ14: =SUM(BD_MR_RF[[#This Row],[Desviación de Color]]+BD_MR_RF[[#This Row],[Sobremaduro]]+BD_MR_RF[[#This Row],[Daño Mécanico]]+BD_MR_RF[[#This Row],[Daño Insecto]]+BD_MR_RF[[#This Row],[Block]]+BD_MR_RF[[#This Row],[Mohos]]) -> 100 | BA14: =SUM(BD_MR_RF[[#This Row],[% Desv. Color (≤5%)]]+BD_MR_RF[[#This Row],[% Sobremaduro (≤6%)]]+BD_MR_RF[[#This Row],[% Daño Mécanico (≤6%)]]+BD_MR_RF[[#This Row],[% Daño Insc. (≤5%)]]+BD_MR_RF[[#This Row],[% Block (≤5%)]]+BD_MR_RF[[#This Row],[% Mohos (0%)]]) -> 0.1 | BB14: S/O | BC14: =1-BD_MR_RF[[#This Row],[% Defectos]] -> 0.9 | BD14: Benjamin Navarro | BE14: =SUM(BD_MR_RF[[#This Row],[Palos (Un.) (≤18)]:[Larvas (Un.) (≤24)]]) -> 0 | BF14: =SUM(BD_MR_RF[[#This Row],[Vidrio (Un.) (0)]:[Plástico (Un.) (0)]]) -> 0 | BG14: =IF(ISBLANK(BD_MR_RF[[#This Row],[Descripción del Producto]]),"",BD_MR_RF[[#This Row],[Descripción del Producto]]) -> MO S/V Org. S/C PSP 12 kg en Caja | BH14: =IF(ISBLANK(BD_MR_RF[[#This Row],[N° Lote]]),"",BD_MR_RF[[#This Row],[N° Lote]]) -> 7830 | BI14: =IF(ISBLANK(BD_MR_RF[[#This Row],[N° Pallet]]),"",BD_MR_RF[[#This Row],[N° Pallet]]) -> 21253
A15: 46037 | B15: =_xlfn.ISOWEEKNUM(BD_MR_RF[[#This Row],[Fecha]]) -> 3 | C15: 1 | D15: 3 | E15: 304231000 | F15: =IFERROR("" & _xlfn.XLOOKUP(BD_MR_RF[[#This Row],[Código]],BD_Cod!A:A,BD_Cod!B:B), "") -> MO S/V Org. S/C PSP 12 kg en Caja | G15: =IFERROR(" " &_xlfn.XLOOKUP(BD_MR_RF[[#This Row],[Código]],BD_Cod!A:A,BD_Cod!H:H," ")," ") -> PSP | H15: 21254 | I15: 7830 | J15: 1000 | K15: 0.49166667 | L15: N/A | M15: 12560 | N15: -12.2 | O15: C | P15: C | Q15: =1-BD_MR_RF[[#This Row],[% Defectos]] -> 0.883 | R15: 26 | S15: =+IFERROR((BD_MR_RF[[#This Row],[Desviación de Color]]/BD_MR_RF[[#This Row],[Muestra]]),"0") -> 0.026 | T15: 0 | U15: =+IFERROR((BD_MR_RF[[#This Row],[Sobremaduro]]/BD_MR_RF[[#This Row],[Muestra]]),"0") -> 0 | V15: 0 | W15: =+IFERROR((BD_MR_RF[[#This Row],[Daño Mécanico]]/BD_MR_RF[[#This Row],[Muestra]]),"0") -> 0 | X15: 62 | Y15: =+IFERROR((BD_MR_RF[[#This Row],[Daño Insecto]]/BD_MR_RF[[#This Row],[Muestra]]),"0") -> 0.062 | Z15: 23 | AA15: =+IFERROR((BD_MR_RF[[#This Row],[Block]]/BD_MR_RF[[#This Row],[Muestra]]),"0") -> 0.023 | AB15: 6 | AC15: =+IFERROR((BD_MR_RF[[#This Row],[Mohos]]/BD_MR_RF[[#This Row],[Muestra]]),"0") -> 0.006 | AD15: 0 | AE15: 0 | AG15: 0 | AH15: =+IFERROR((BD_MR_RF[[#This Row],[Valor Extra 1]]/BD_MR_RF[[#This Row],[Muestra]]),"0") -> 0 | AJ15: 0 | AK15: =+IFERROR((BD_MR_RF[[#This Row],[Valor Extra 2]]/BD_MR_RF[[#This Row],[Muestra]]),"0") -> 0 | AL15: 0 | AM15: =+IFERROR((BD_MR_RF[[#This Row],[Calibre >16]]/BD_MR_RF[[#This Row],[Muestra]]),"0") -> 0 | AN15: 0 | AO15: =+IFERROR((BD_MR_RF[[#This Row],[Calibre <16]]/BD_MR_RF[[#This Row],[Muestra]]),"0") -> 0 | AP15: S/A | AQ15: S/A | AR15: S/A | AS15: S/A | AT15: S/A | AU15: S/A | AV15: S/A | AW15: 15.6 | AX15: C | AY15: C | AZ15: =SUM(BD_MR_RF[[#This Row],[Desviación de Color]]+BD_MR_RF[[#This Row],[Sobremaduro]]+BD_MR_RF[[#This Row],[Daño Mécanico]]+BD_MR_RF[[#This Row],[Daño Insecto]]+BD_MR_RF[[#This Row],[Block]]+BD_MR_RF[[#This Row],[Mohos]]) -> 117 | BA15: =SUM(BD_MR_RF[[#This Row],[% Desv. Color (≤5%)]]+BD_MR_RF[[#This Row],[% Sobremaduro (≤6%)]]+BD_MR_RF[[#This Row],[% Daño Mécanico (≤6%)]]+BD_MR_RF[[#This Row],[% Daño Insc. (≤5%)]]+BD_MR_RF[[#This Row],[% Block (≤5%)]]+BD_MR_RF[[#This Row],[% Mohos (0%)]]) -> 0.117 | BB15: S/O | BC15: =1-BD_MR_RF[[#This Row],[% Defectos]] -> 0.883 | BD15: Benjamin Navarro | BE15: =SUM(BD_MR_RF[[#This Row],[Palos (Un.) (≤18)]:[Larvas (Un.) (≤24)]]) -> 0 | BF15: =SUM(BD_MR_RF[[#This Row],[Vidrio (Un.) (0)]:[Plástico (Un.) (0)]]) -> 0 | BG15: =IF(ISBLANK(BD_MR_RF[[#This Row],[Descripción del Producto]]),"",BD_MR_RF[[#This Row],[Descripción del Producto]]) -> MO S/V Org. S/C PSP 12 kg en Caja | BH15: =IF(ISBLANK(BD_MR_RF[[#This Row],[N° Lote]]),"",BD_MR_RF[[#This Row],[N° Lote]]) -> 7830 | BI15: =IF(ISBLANK(BD_MR_RF[[#This Row],[N° Pallet]]),"",BD_MR_RF[[#This Row],[N° Pallet]]) -> 21254
A16: 46037 | B16: =_xlfn.ISOWEEKNUM(BD_MR_RF[[#This Row],[Fecha]]) -> 3 | C16: 1 | D16: 3 | E16: 304231000 | F16: =IFERROR("" & _xlfn.XLOOKUP(BD_MR_RF[[#This Row],[Código]],BD_Cod!A:A,BD_Cod!B:B), "") -> MO S/V Org. S/C PSP 12 kg en Caja | G16: =IFERROR(" " &_xlfn.XLOOKUP(BD_MR_RF[[#This Row],[Código]],BD_Cod!A:A,BD_Cod!H:H," ")," ") -> PSP | H16: 21255 | I16: 7830 | J16: 1000 | K16: 0.54027778 | L16: N/A | M16: 12595 | N16: -15.5 | O16: C | P16: C | Q16: =1-BD_MR_RF[[#This Row],[% Defectos]] -> 0.831 | R16: 26 | S16: =+IFERROR((BD_MR_RF[[#This Row],[Desviación de Color]]/BD_MR_RF[[#This Row],[Muestra]]),"0") -> 0.026 | T16: 0 | U16: =+IFERROR((BD_MR_RF[[#This Row],[Sobremaduro]]/BD_MR_RF[[#This Row],[Muestra]]),"0") -> 0 | V16: 0 | W16: =+IFERROR((BD_MR_RF[[#This Row],[Daño Mécanico]]/BD_MR_RF[[#This Row],[Muestra]]),"0") -> 0 | X16: 143 | Y16: =+IFERROR((BD_MR_RF[[#This Row],[Daño Insecto]]/BD_MR_RF[[#This Row],[Muestra]]),"0") -> 0.143 | Z16: 0 | AA16: =+IFERROR((BD_MR_RF[[#This Row],[Block]]/BD_MR_RF[[#This Row],[Muestra]]),"0") -> 0 | AB16: 0 | AC16: =+IFERROR((BD_MR_RF[[#This Row],[Mohos]]/BD_MR_RF[[#This Row],[Muestra]]),"0") -> 0 | AD16: 0 | AE16: 0 | AG16: 0 | AH16: =+IFERROR((BD_MR_RF[[#This Row],[Valor Extra 1]]/BD_MR_RF[[#This Row],[Muestra]]),"0") -> 0 | AJ16: 0 | AK16: =+IFERROR((BD_MR_RF[[#This Row],[Valor Extra 2]]/BD_MR_RF[[#This Row],[Muestra]]),"0") -> 0 | AL16: 0 | AM16: =+IFERROR((BD_MR_RF[[#This Row],[Calibre >16]]/BD_MR_RF[[#This Row],[Muestra]]),"0") -> 0 | AN16: 0 | AO16: =+IFERROR((BD_MR_RF[[#This Row],[Calibre <16]]/BD_MR_RF[[#This Row],[Muestra]]),"0") -> 0 | AP16: S/A | AQ16: S/A | AR16: S/A | AS16: S/A | AT16: S/A | AU16: S/A | AV16: S/A | AW16: 13.5 | AX16: C | AY16: C | AZ16: =SUM(BD_MR_RF[[#This Row],[Desviación de Color]]+BD_MR_RF[[#This Row],[Sobremaduro]]+BD_MR_RF[[#This Row],[Daño Mécanico]]+BD_MR_RF[[#This Row],[Daño Insecto]]+BD_MR_RF[[#This Row],[Block]]+BD_MR_RF[[#This Row],[Mohos]]) -> 169 | BA16: =SUM(BD_MR_RF[[#This Row],[% Desv. Color (≤5%)]]+BD_MR_RF[[#This Row],[% Sobremaduro (≤6%)]]+BD_MR_RF[[#This Row],[% Daño Mécanico (≤6%)]]+BD_MR_RF[[#This Row],[% Daño Insc. (≤5%)]]+BD_MR_RF[[#This Row],[% Block (≤5%)]]+BD_MR_RF[[#This Row],[% Mohos (0%)]]) -> 0.169 | BB16: S/O | BC16: =1-BD_MR_RF[[#This Row],[% Defectos]] -> 0.831 | BD16: Benjamin Navarro | BE16: =SUM(BD_MR_RF[[#This Row],[Palos (Un.) (≤18)]:[Larvas (Un.) (≤24)]]) -> 0 | BF16: =SUM(BD_MR_RF[[#This Row],[Vidrio (Un.) (0)]:[Plástico (Un.) (0)]]) -> 0 | BG16: =IF(ISBLANK(BD_MR_RF[[#This Row],[Descripción del Producto]]),"",BD_MR_RF[[#This Row],[Descripción del Producto]]) -> MO S/V Org. S/C PSP 12 kg en Caja | BH16: =IF(ISBLANK(BD_MR_RF[[#This Row],[N° Lote]]),"",BD_MR_RF[[#This Row],[N° Lote]]) -> 7830 | BI16: =IF(ISBLANK(BD_MR_RF[[#This Row],[N° Pallet]]),"",BD_MR_RF[[#This Row],[N° Pallet]]) -> 21255
A17: 46037 | B17: =_xlfn.ISOWEEKNUM(BD_MR_RF[[#This Row],[Fecha]]) -> 3 | C17: 1 | D17: 3 | E17: 304231000 | F17: =IFERROR("" & _xlfn.XLOOKUP(BD_MR_RF[[#This Row],[Código]],BD_Cod!A:A,BD_Cod!B:B), "") -> MO S/V Org. S/C PSP 12 kg en Caja | G17: =IFERROR(" " &_xlfn.XLOOKUP(BD_MR_RF[[#This Row],[Código]],BD_Cod!A:A,BD_Cod!H:H," ")," ") -> PSP | H17: 21519 | I17: 7830 | J17: 1000 | K17: 0.58611111 | L17: N/A | M17: 12550 | N17: -12 | O17: C | P17: C | Q17: =1-BD_MR_RF[[#This Row],[% Defectos]] -> 0.866 | R17: 4 | S17: =+IFERROR((BD_MR_RF[[#This Row],[Desviación de Color]]/BD_MR_RF[[#This Row],[Muestra]]),"0") -> 0.004 | T17: 0 | U17: =+IFERROR((BD_MR_RF[[#This Row],[Sobremaduro]]/BD_MR_RF[[#This Row],[Muestra]]),"0") -> 0 | V17: 9 | W17: =+IFERROR((BD_MR_RF[[#This Row],[Daño Mécanico]]/BD_MR_RF[[#This Row],[Muestra]]),"0") -> 0.009 | X17: 121 | Y17: =+IFERROR((BD_MR_RF[[#This Row],[Daño Insecto]]/BD_MR_RF[[#This Row],[Muestra]]),"0") -> 0.121 | Z17: 0 | AA17: =+IFERROR((BD_MR_RF[[#This Row],[Block]]/BD_MR_RF[[#This Row],[Muestra]]),"0") -> 0 | AB17: 0 | AC17: =+IFERROR((BD_MR_RF[[#This Row],[Mohos]]/BD_MR_RF[[#This Row],[Muestra]]),"0") -> 0 | AD17: 0 | AE17: 0 | AF17: deshidratado | AG17: 2 | AH17: =+IFERROR((BD_MR_RF[[#This Row],[Valor Extra 1]]/BD_MR_RF[[#This Row],[Muestra]]),"0") -> 0.002 | AJ17: 0 | AK17: =+IFERROR((BD_MR_RF[[#This Row],[Valor Extra 2]]/BD_MR_RF[[#This Row],[Muestra]]),"0") -> 0 | AL17: 0 | AM17: =+IFERROR((BD_MR_RF[[#This Row],[Calibre >16]]/BD_MR_RF[[#This Row],[Muestra]]),"0") -> 0 | AN17: 0 | AO17: =+IFERROR((BD_MR_RF[[#This Row],[Calibre <16]]/BD_MR_RF[[#This Row],[Muestra]]),"0") -> 0 | AP17: S/A | AQ17: S/A | AR17: S/A | AS17: S/A | AT17: S/A | AU17: S/A | AV17: S/A | AW17: 12.2 | AX17: C | AY17: C | AZ17: =SUM(BD_MR_RF[[#This Row],[Desviación de Color]]+BD_MR_RF[[#This Row],[Sobremaduro]]+BD_MR_RF[[#This Row],[Daño Mécanico]]+BD_MR_RF[[#This Row],[Daño Insecto]]+BD_MR_RF[[#This Row],[Block]]+BD_MR_RF[[#This Row],[Mohos]]) -> 134 | BA17: =SUM(BD_MR_RF[[#This Row],[% Desv. Color (≤5%)]]+BD_MR_RF[[#This Row],[% Sobremaduro (≤6%)]]+BD_MR_RF[[#This Row],[% Daño Mécanico (≤6%)]]+BD_MR_RF[[#This Row],[% Daño Insc. (≤5%)]]+BD_MR_RF[[#This Row],[% Block (≤5%)]]+BD_MR_RF[[#This Row],[% Mohos (0%)]]) -> 0.134 | BB17: S/O | BC17: =1-BD_MR_RF[[#This Row],[% Defectos]] -> 0.866 | BD17: Fernanda Delgado | BE17: =SUM(BD_MR_RF[[#This Row],[Palos (Un.) (≤18)]:[Larvas (Un.) (≤24)]]) -> 0 | BF17: =SUM(BD_MR_RF[[#This Row],[Vidrio (Un.) (0)]:[Plástico (Un.) (0)]]) -> 0 | BG17: =IF(ISBLANK(BD_MR_RF[[#This Row],[Descripción del Producto]]),"",BD_MR_RF[[#This Row],[Descripción del Producto]]) -> MO S/V Org. S/C PSP 12 kg en Caja | BH17: =IF(ISBLANK(BD_MR_RF[[#This Row],[N° Lote]]),"",BD_MR_RF[[#This Row],[N° Lote]]) -> 7830 | BI17: =IF(ISBLANK(BD_MR_RF[[#This Row],[N° Pallet]]),"",BD_MR_RF[[#This Row],[N° Pallet]]) -> 21519
A18: 46037 | B18: =_xlfn.ISOWEEKNUM(BD_MR_RF[[#This Row],[Fecha]]) -> 3 | C18: 1 | D18: 3 | E18: 304231000 | F18: =IFERROR("" & _xlfn.XLOOKUP(BD_MR_RF[[#This Row],[Código]],BD_Cod!A:A,BD_Cod!B:B), "") -> MO S/V Org. S/C PSP 12 kg en Caja | G18: =IFERROR(" " &_xlfn.XLOOKUP(BD_MR_RF[[#This Row],[Código]],BD_Cod!A:A,BD_Cod!H:H," ")," ") -> PSP | H18: 21520 | I18: 7830 | J18: 1000 | K18: 0.59375 | L18: N/A | M18: 12555 | N18: -14.2 | O18: C | P18: C | Q18: =1-BD_MR_RF[[#This Row],[% Defectos]] -> 0.916 | R18: 43 | S18: =+IFERROR((BD_MR_RF[[#This Row],[Desviación de Color]]/BD_MR_RF[[#This Row],[Muestra]]),"0") -> 0.043 | T18: 0 | U18: =+IFERROR((BD_MR_RF[[#This Row],[Sobremaduro]]/BD_MR_RF[[#This Row],[Muestra]]),"0") -> 0 | V18: 0 | W18: =+IFERROR((BD_MR_RF[[#This Row],[Daño Mécanico]]/BD_MR_RF[[#This Row],[Muestra]]),"0") -> 0 | X18: 27 | Y18: =+IFERROR((BD_MR_RF[[#This Row],[Daño Insecto]]/BD_MR_RF[[#This Row],[Muestra]]),"0") -> 0.027 | Z18: 11 | AA18: =+IFERROR((BD_MR_RF[[#This Row],[Block]]/BD_MR_RF[[#This Row],[Muestra]]),"0") -> 0.011 | AB18: 3 | AC18: =+IFERROR((BD_MR_RF[[#This Row],[Mohos]]/BD_MR_RF[[#This Row],[Muestra]]),"0") -> 0.003 | AD18: 3 | AE18: 0 | AF18: deshidratado | AG18: 4 | AH18: =+IFERROR((BD_MR_RF[[#This Row],[Valor Extra 1]]/BD_MR_RF[[#This Row],[Muestra]]),"0") -> 0.004 | AJ18: 0 | AK18: =+IFERROR((BD_MR_RF[[#This Row],[Valor Extra 2]]/BD_MR_RF[[#This Row],[Muestra]]),"0") -> 0 | AL18: 0 | AM18: =+IFERROR((BD_MR_RF[[#This Row],[Calibre >16]]/BD_MR_RF[[#This Row],[Muestra]]),"0") -> 0 | AN18: 0 | AO18: =+IFERROR((BD_MR_RF[[#This Row],[Calibre <16]]/BD_MR_RF[[#This Row],[Muestra]]),"0") -> 0 | AP18: S/A | AQ18: S/A | AR18: S/A | AS18: S/A | AT18: S/A | AU18: S/A | AV18: S/A | AW18: 14.1 | AX18: C | AY18: C | AZ18: =SUM(BD_MR_RF[[#This Row],[Desviación de Color]]+BD_MR_RF[[#This Row],[Sobremaduro]]+BD_MR_RF[[#This Row],[Daño Mécanico]]+BD_MR_RF[[#This Row],[Daño Insecto]]+BD_MR_RF[[#This Row],[Block]]+BD_MR_RF[[#This Row],[Mohos]]) -> 84 | BA18: =SUM(BD_MR_RF[[#This Row],[% Desv. Color (≤5%)]]+BD_MR_RF[[#This Row],[% Sobremaduro (≤6%)]]+BD_MR_RF[[#This Row],[% Daño Mécanico (≤6%)]]+BD_MR_RF[[#This Row],[% Daño Insc. (≤5%)]]+BD_MR_RF[[#This Row],[% Block (≤5%)]]+BD_MR_RF[[#This Row],[% Mohos (0%)]]) -> 0.084 | BB18: S/O | BC18: =1-BD_MR_RF[[#This Row],[% Defectos]] -> 0.916 | BD18: Fernanda Delgado | BE18: =SUM(BD_MR_RF[[#This Row],[Palos (Un.) (≤18)]:[Larvas (Un.) (≤24)]]) -> 0 | BF18: =SUM(BD_MR_RF[[#This Row],[Vidrio (Un.) (0)]:[Plástico (Un.) (0)]]) -> 0 | BG18: =IF(ISBLANK(BD_MR_RF[[#This Row],[Descripción del Producto]]),"",BD_MR_RF[[#This Row],[Descripción del Producto]]) -> MO S/V Org. S/C PSP 12 kg en Caja | BH18: =IF(ISBLANK(BD_MR_RF[[#This Row],[N° Lote]]),"",BD_MR_RF[[#This Row],[N° Lote]]) -> 7830 | BI18: =IF(ISBLANK(BD_MR_RF[[#This Row],[N° Pallet]]),"",BD_MR_RF[[#This Row],[N° Pallet]]) -> 21520
